<mujoco model="swimmer">
  <compiler angle="degree" coordinate="local" inertiafromgeom="true" meshdir="mesh" texturedir="textures"/>
  <option collision="predefined" density="4000" integrator="RK4" timestep="0.01" viscosity="0.1"/>  
  <option gravity="0 0 -9.81" integrator="Euler" iterations="20" timestep=".01" />

  <default>
    <!-- controls rope and color  -->
      <joint armature="0.04" damping="1"/>
      <geom conaffinity="0" condim="1" contype="0" density="10" friction=".8 .1 .1" margin="0.002" rgba="0.8 0.6 .4 1" />
  </default>

  <worldbody>
    <light cutoff="100" diffuse="1 1 1" dir="-0 0 -1" directional="true" exponent="1" pos="0 0 0.0" specular=".1 .1 .1"/>

    <geom rgba="0.1 0.1 .1 1." conaffinity="1" density='0.' contype="1" condim="1" name="table" pos="0 0.0 0." size="2.8 2.8 0.1" type="plane" />
    <!--  ================= SWIMMER ================= /-->
    <body name="torso" pos="0 0 0">
      <geom density="1000" fromto="1.5 0 0 0.5 0 0" size="0.1" type="capsule"/>
      <joint axis="1 0 0" name="slider1" pos="0 0 0" type="slide"/>
      <joint axis="0 1 0" name="slider2" pos="0 0 0" type="slide"/>
      <joint axis="0 0 1" name="rot" pos="0 0 0" type="hinge"/>
      <body name="mid" pos="0.5 0 0">
        <geom density="1000" fromto="0 0 0 -1 0 0" size="0.1" type="capsule"/>
        <joint axis="0 0 1" limited="true" name="rot2" pos="0 0 0" range="-100 100" type="hinge"/>
        <body name="back" pos="-1 0 0">
          <geom density="1000" fromto="0 0 0 -1 0 0" size="0.1" type="capsule"/>
          <joint axis="0 0 1" limited="true" name="rot3" pos="0 0 0" range="-100 100" type="hinge"/>
        </body>
      </body>
    </body>
  </worldbody>
  <actuator>
    <motor ctrllimited="true" ctrlrange="-1 1" gear="150.0" joint="rot2"/>
    <motor ctrllimited="true" ctrlrange="-1 1" gear="150.0" joint="rot3"/>
  </actuator>
</mujoco>
