<mujoco model="swimmer">
  <compiler angle="degree" coordinate="local" inertiafromgeom="true" meshdir="mesh" texturedir="textures"/>
<!--   <option collision="predefined" density="4000" integrator="RK4" timestep="0.01" viscosity="0.1"/>  
 -->  <option gravity="0 0 -9.81" integrator="Euler" iterations="20" timestep=".01" />
  <default>
    <!-- controls rope and color  -->
      <joint armature="0.04" damping="1"/>
      <geom conaffinity="1" condim="3" contype="1" density="10" friction=".8 .1 .1" margin="0.002" rgba="0.8 0.6 .4 1" />
  </default>

  <worldbody>
    <light cutoff="100" diffuse="1 1 1" dir="-0 0 -1" directional="true" exponent="1" pos="0 0 0.0" specular=".1 .1 .1"/>

    <geom rgba="0.1 0.1 .1 1." conaffinity="1" density='0.' contype="1" condim="1" name="table" pos="0 0.0 0." size="2.8 2.8 0.1" type="plane" />
    <!--  ================= SWIMMER ================= /-->
    <body name="torso" pos="0 0 .12" >
      <geom density="30" name="pointbody" type="sphere" size="0.01" pos="0 0 0"  />
      <joint name='ballx' type='slide' axis='1 0 0' pos='0 0 0.1' />
      <joint name='bally' type='slide' axis='0 1 0' pos='0 0 0.1' />
      <joint name='rot' type='hinge' axis='0 0 1' pos='0 0 0' limited="false" />
      <body name="torso2" pos="0 0 0">
          <geom density="30" fromto="0 0 0 -1 0 0" size="0.1" type="capsule" rgba="0 1 0 1" />
          <joint axis="0 0 1" name="rot2" pos="0 0 0" type="hinge"/>
          <body name="mid" pos="-1 0 0">
            <geom density="30" fromto="0 0 0 -1 0 0" size="0.1" type="capsule"/>
            <joint axis="0 0 1" limited="false" name="rot3" pos="0 0 0" type="hinge"/>
            
            <body name="back2" pos="-1 0 0">
              <geom density="30" fromto="0 0 0 -1 0 0" size="0.1" type="capsule"/>
              <joint axis="0 0 1" name="rot5" pos="0 0 0" type="hinge"/>
              
<!--               <body name="back" pos="-.5 0 .1">
                <geom density="30000" name="pointbody2" type="sphere" size="0.1" pos="0 0 0" rgba="1 0.1 .1 1."/>
                <joint name='ballx2' type='slide' axis='1 0 0' pos='0 0 0' />
                <joint name='bally2' type='slide' axis='0 1 0' pos='0 0 0' />
                <joint name='rot4' type='hinge' axis='0 0 1' pos='0 0 0' limited="false" /> -->
<!--             </body> -->
          </body>
        </body>
      </body>
    </body>
    
  </worldbody>


<!--  <worldbody>-->
<!--        <body name="obs1" pos = ".9 1.1 .14">-->
<!--          <geom conaffinity="1" contype="1" condim="3"  pos="0. 0. 0." size=".1 1.2 0.16" rgba="1.0  0.0 0.0 1" type="box" friction="2 2 2"/>-->
<!--        </body>-->
<!--        <body name="obs2" pos = "-.9 -1.1 .14">-->
<!--          <geom conaffinity="1" contype="1" condim="3"  pos="0. 0. 0." size=".1 1.2 0.16" rgba="1.0  0.0 0.0 1" type="box" friction="2 2 2"/>-->
<!--        </body>-->

<!--        <body name="north" pos = "0 2.6 .14">-->
<!--          <geom conaffinity="1" contype="1" condim="3"  pos="0. 0. 0." size="3.0 .2 0.16" rgba="0. 0. 0. 1" type="box" friction="2 2 2"/>-->
<!--        </body>-->
<!--        <body name="south" pos = ".0 -2.6 .14">-->
<!--          <geom conaffinity="1" contype="1" condim="3"  pos="0. 0. 0." size="3 .2 0.16" rgba=".0  0. 0. 1" type="box" friction="2 2 2"/>-->
<!--        </body>-->

<!--        <body name="east" pos = "2.6 0 .14">-->
<!--          <geom conaffinity="1" contype="1" condim="3"  pos="0. 0. 0." size=".2 3 0.16" rgba="0. 0. 0. 1" type="box" friction="2 2 2"/>-->
<!--        </body>-->
<!--        <body name="west" pos = "-2.6 0 .14">-->
<!--          <geom conaffinity="1" contype="1" condim="3"  pos="0. 0. 0." size=".2 3 0.16" rgba=".0  0. 0. 1" type="box" friction="2 2 2"/>-->
<!--        </body>-->
<!--  </worldbody>  -->

  
  <actuator>
    <motor ctrllimited="false" ctrlrange="-1 1" gear="200.0" joint="ballx"/>
    <motor ctrllimited="false" ctrlrange="-1 1" gear="200.0" joint="bally"/>   
<!--     <motor ctrllimited="false" ctrlrange="-1 1" gear="100.0" joint="ballx2"/>
    <motor ctrllimited="false" ctrlrange="-1 1" gear="100.0" joint="bally2"/>
 -->
  </actuator>
</mujoco>
